Workbook

Sheet 指标统计
A1: 尚桐数据 | B1: 指标类型 | E1: 年份 | F1: 累计 | G1: 1月 | H1: 2月 | I1: 3月 | J1: 4月 | K1: 5月 | L1: 6月 | M1: 7月 | N1: 8月 | O1: 9月 | P1: 10月 | Q1: 11月 | R1: 12月
B2: 安全事故量 | E2: 2024 | F2: 112 | G2: 18 | H2: 19 | I2: 18 | J2: 30 | K2: 27 | L2: 32 | M2: 33 | N2: 50 | O2: 37 | P2: 42 | Q2: 45 | R2: 41
E3: 2025 | F3: 126 | G3: 20 | H3: 31 | I3: 32 | J3: 18 | K3: 25
B4: 二十万工时事故率 | E4: 2024 | F4: 0.63 | G4: 0.36 | H4: 0.24 | I4: 0.52 | J4: 0.56 | K4: 0.62 | L4: 0.67 | M4: 0.65 | N4: 0.97 | O4: 0.68 | P4: 0.72 | Q4: 0.7 | R4: 0.72
E5: 2025 | F5: 0.36 | G5: 0.37 | H5: 0.46 | I5: 0.22
A7: 新数据 | B7: 指标类型 | C7: 应用标准：健康度唯独 | E7: 年份 | F7: 累计 | G7: 1月 | H7: 2月 | I7: 3月 | J7: 4月 | K7: 5月 | L7: 6月 | M7: 7月 | N7: 8月 | O7: 9月 | P7: 10月 | Q7: 11月 | R7: 12月 | S7: 汇总
B8: 安全事故量 | D8: 事故量 | E8: 2023 | F8: =SUM(G8:R8) -> 238 | G8: 18 | H8: 19 | I8: 18 | J8: 30 | K8: 21 | L8: 13 | M8: 19 | N8: 15 | O8: 16 | P8: 20 | Q8: 22 | R8: 27 | S8: =SUM(G8:R8) -> 238
E9: 2024 | F9: =SUM(G9:R9) -> 325 | G9: 18 | H9: 7 | I9: 20 | J9: 28 | K9: 30 | L9: 34 | M9: 26 | N9: 37 | O9: 27 | P9: 34 | Q9: 34 | R9: 30 | S9: =SUM(G9:R9) -> 325
E10: 2025 | F10: =SUM(G10:R10) -> 319 | G10: 22 | H10: 33 | I10: 29 | J10: 18 | K10: 25 | L10: 27 | M10: 28 | N10: 27 | O10: 36 | P10: 25 | Q10: 29 | R10: 20 | S10: =SUM(G10:R10) -> 319
B11: 工时 | D11: 工时 | E11: 2023 | F11: =SUM(G11:R11) -> 120340705 | G11: 6437440 | H11: 8549416 | I11: 9292640 | J11: 8853608 | K11: 9523512 | L11: 9804424 | M11: 9526752 | N11: 9467864 | O11: 10293752 | P11: 10506432 | Q11: 10893336 | R11: 17191529 | S11: =SUM(G11:R11) -> 120340705
E12: 2024 | F12: =SUM(G12:R12) -> 154976190 | G12: 13029750 | H12: 8207940 | I12: 12868270 | J12: 11989600 | K12: 12929950 | L12: 13047930 | M12: 13405790 | N12: 13140000 | O12: 13144940 | P12: 14485140 | Q12: 14281280 | R12: 14445600 | S12: =SUM(G12:R12) -> 154976190
E13: 2025 | F13: =SUM(G13:R13) -> 164125910 | G13: 12020220 | H13: 11698910 | I13: 14024940 | J13: 13425850 | K13: 14214090 | L13: 14014220 | M13: 14428630 | N13: 14528510 | O13: 14658390 | P13: 15257950 | Q13: 15491820 | R13: 10362380 | S13: =SUM(G13:R13) -> 164125910
B14: 二十万工时事故率 | D14: 20万工时事故率 | E14: 2023 | F14: =F8/F11*200000 -> 0.39554364 | G14: =G8/G11*200000 -> 0.55922851 | H14: =H8/H11*200000 -> 0.4444748 | I14: =I8/I11*200000 -> 0.38740336 | J14: =J8/J11*200000 -> 0.67768982 | K14: =K8/K11*200000 -> 0.44101378 | L14: =L8/L11*200000 -> 0.26518641 | M14: =M8/M11*200000 -> 0.39887676 | ... S14: =S8/S11*200000 -> 0.39554364
E15: 2024 | F15: =F9/F12*200000 -> 0.41941927 | G15: =G9/G12*200000 -> 0.2762908 | H15: =H9/H12*200000 -> 0.17056655 | I15: =I9/I12*200000 -> 0.31084209 | J15: =J9/J12*200000 -> 0.46707146 | K15: =K9/K12*200000 -> 0.46403892 | L15: =L9/L12*200000 -> 0.52115546 | M15: =M9/M12*200000 -> 0.3878921 | ... S15: =S9/S12*200000 -> 0.41941927
E16: 2025 | F16: =F10/F13*200000 -> 0.38872595 | G16: =G10/G13*200000 -> 0.36604987 | H16: =H10/H13*200000 -> 0.56415512 | I16: =I10/I13*200000 -> 0.41354901 | J16: =J10/J13*200000 -> 0.26813945 | K16: =K10/K13*200000 -> 0.35176364 | L16: =L10/L13*200000 -> 0.38532291 | M16: =M10/M13*200000 -> 0.38811724 | ... S16: =S10/S13*200000 -> 0.38872595
C17: 数据截至12月20日 9月工时和12月工时为昆仑人员分析用工管理在职人数统计口径

Sheet 25年安全事故明细（1-12月）
A1: 序号 | B1: 姓名 | C1: 所属单位 | D1: 省区 | E1: 大区 | F1: 出险日期 | G1: 月份 | H1: 出险情况说明 | I1: 受伤部位 | J1: 事故详细类型 | K1: 判定依据 | L1: 判责 | M1: 主责任方 | N1: 事故费用 | O1: 是否考核中心 | P1: 健康度评价 | Q1: 备注 | R1: sto上报 | S1: OA上报
A2: 1 | B2: 李晓午 | C2: 福建泉州转运中心 | D2: 福建 | E2: =VLOOKUP(C2,#REF!,3,0) -> #REF! | F2: 45658 | G2: =MONTH(F2) -> 1 | H2: 员工梳堵过程中，被破损货物（内品，镰刀）割伤。 | I2: 血管断裂，部分肌腱断裂 | J2: 割伤类 | L2: 责任 | M2: 个人 | O2: 是 | P2: 否
A3: 2 | B3: 胡欢 | C3: 贵州贵阳转运中心 | D3: 贵州 | E3: =VLOOKUP(C3,#REF!,3,0) -> #REF! | F3: 45659 | G3: =MONTH(F3) -> 1 | H3: 白班员工胡欢(工号1190499）在自动化集包区域活动被滑槽的可活动的延伸装置夹到手 | I3: 手指损伤，指骨骨折 | J3: 机械类 | L3: 责任 | M3: 中心
A4: 3 | B4: 郑翠翠 | C4: 河北邯郸转运中心 | D4: 京津冀 | E4: =VLOOKUP(C4,#REF!,3,0) -> #REF! | F4: 45659 | G4: =MONTH(F4) -> 1 | H4: 25年1月2日晚22:01:53秒，DWS称重扫描员，郑翠翠1061712，在通过卸货口处理错分件，途中失足踩空，跌落摔伤。 | I4: 昏迷，有脑出血现象 | J4: 摔伤类 | L4: 责任 | M4: 个人
A5: 4 | B5: 赵年香 | C5: 湖南长沙转运中心 | D5: 湖南 | E5: =VLOOKUP(C5,#REF!,3,0) -> #REF! | F5: 45660 | G5: =MONTH(F5) -> 1 | H5: 2025年1月3日下午19：00左右，出港晚班班长赵年香（1023996，女，50岁）上班前往岗位途中在3F出港矩阵下方通道摔倒，立即送往长沙市中心医院检查 | I5: 左腕三角骨撕脱骨折 | J5: 摔伤类 | L5: 责任 | M5: 个人
A6: 5 | B6: 余森 | C6: 湖北武昌转运中心 | D6: 湖北 | E6: =VLOOKUP(C6,#REF!,3,0) -> #REF! | F6: 45661 | G6: =MONTH(F6) -> 1 | H6: 进港员工余森（工号1201343）拉回流件过程中右手不慎撞到矩阵线体立柱。 | I6: 右手掌裂伤，缝合2针，无骨拆 | J6: 撞伤类 | L6: 责任 | M6: 个人
A7: 6 | B7: 赵志雄 | C7: 四川南充转运中心 | D7: 川藏 | E7: =VLOOKUP(C7,#REF!,3,0) -> #REF! | F7: 45664 | G7: =MONTH(F7) -> 1 | H7: 破损处理员-赵志雄（1284171）协助三方邦友达对运营中的摆臂紧急抢修过程中，被复位摆臂夹伤手。 | I7: 右手指骨有轻微断离 | J7: 机械类 | L7: 责任 | M7: 三方
A8: 7 | B8: 杜兴旺 | C8: 河北保定转运中心 | D8: 京津冀 | E8: =VLOOKUP(C8,#REF!,3,0) -> #REF! | F8: 45665 | G8: =MONTH(F8) -> 1 | H8: 出港6号线装车杜兴旺（男，工号1297958）4点2分在装合肥车时不慎从伸缩机前端跌落，随后继续工作至6点员工感觉疼痛后去医院。 | I8: 右侧第6肋骨骨折 | J8: 摔伤类 | L8: 责任 | M8: 个人
A9: 8 | B9: 罗艳兰 | C9: 江西南昌转运中心 | D9: 江西 | E9: =VLOOKUP(C9,#REF!,3,0) -> #REF! | F9: 45666 | G9: =MONTH(F9) -> 1 | H9: 进港白班员工罗艳兰，工号1221064，在女厕所踩空滑倒，导致脚部扭伤，已被班组长送至医院，医院CT做完后显示脚踝骨裂 | I9: 胫腓骨下端骨折 | J9: 摔伤类 | L9: 责任 | M9: 个人
A10: 9 | B10: 吕军华 | C10: 山东济南转运中心 | D10: 山东 | E10: =VLOOKUP(C10,#REF!,3,0) -> #REF! | F10: 45666 | G10: =MONTH(F10) -> 1 | H10: 吕军华（岗位，细分拉件员；）2025年1月9日4:20.在出港3号线打扫卫生时，摔倒手部摔伤 | I10: 右腕关节多发性骨折 | J10: 摔伤类 | L10: 责任 | M10: 个人
A11: 10 | B11: 汤丽华 | C11: 湖南长沙转运中心 | D11: 湖南 | E11: =VLOOKUP(C11,#REF!,3,0) -> #REF! | F11: 45666 | G11: =MONTH(F11) -> 1 | H11: 湖南长沙转运中心2025年1月9日上午9:50左右，进港白班员工汤丽华（1026598，女，43岁），在10号DWS处拦截破损件时手指卷入皮带接缝处被夹伤，目前花费700元左右。 | I11: 手指夹伤 | J11: 机械类 | L11: 责任 | M11: 中心
A12: 11 | B12: 贺静 | C12: 江苏徐州转运中心 | D12: 江苏 | E12: =VLOOKUP(C12,#REF!,3,0) -> #REF! | F12: 45667 | G12: =MONTH(F12) -> 1 | H12: 夜班员工 贺静（1299892）在上班途中经过韵达快递门口发生车祸。 | I12: 开放性损伤伴异物，创伤性牙折断 | J12: 场外交通类 | L12: 无责 | M12: -
A13: 12 | B13: 蔡丽苹 | C13: 四川成都转运中心 | D13: 川藏 | E13: =VLOOKUP(C13,#REF!,3,0) -> #REF! | F13: 45669 | G13: =MONTH(F13) -> 1 | H13: 2025年1月12日7点49分左右，侧滑集包班长蔡丽萍（工号1060594）在二楼自动化NC区域关停流水线后（未关停摆臂）通线被摆臂夹手，现人员已前往人民医院进行治疗，后续结果待跟进； | I13: 左手中子指甲粗隆骨折，断端稍分离 | J13: 机械类 | L13: 责任 | M13: 中心
A14: 13 | B14: 卢锋波 | C14: 河南漯河转运中心 | D14: 河南 | E14: =VLOOKUP(C14,#REF!,3,0) -> #REF! | F14: 45669 | G14: =MONTH(F14) -> 1 | H14: 夜班进港员工 卢锋波(1005846)在进港疏通进港11号摆臂下方带时，手不慎伸进上方摆臂齿轮链条内部。 | I14: 左手无名指前关节部分夹掉 中指、食指前关节处不同程度骨折 | J14: 机械类 | L14: 责任 | M14: 中心
... A84: 83 | B84: 朱贺 | C84: 江苏江阴转运中心 | D84: 江苏 | E84: =VLOOKUP(C84,#REF!,3,0) -> #REF! | F84: 45747 | G84: =MONTH(F84) -> 3 | H84: 2025年3月31日晚22点时12分左右。员工朱贺在江阴转运中心华士场地装上海线路货物，抱一重包货物时扭伤右手腕，当时只觉疼痛，下班后至医院拍片检查，检查结果显示右尺骨茎突骨折，医生建议住院治疗 | I84: 右尺骨茎突骨折 | J84: 劳动损伤类 | L84: 无责 | M84: -
A85: 84 | B85: 董怀芝 | C85: 山东济宁转运中心 | D85: 山东 | E85: =VLOOKUP(C85,#REF!,3,0) -> #REF! | F85: 45748 | G85: =MONTH(F85) -> 4 | H85: 董怀芝-自动化供件员，在供件台下楼梯时，背靠楼梯下行，从楼梯摔倒下来。 | I85: 左足踝部外伤 | J85: 摔伤类 | L85: 责任 | M85: 个人 | O85: 否 | P85: 是
A86: 85 | B86: 王自文 | C86: 上海转运中心 | D86: 上海 | E86: =VLOOKUP(C86,#REF!,3,0) -> #REF! | F86: 45748 | G86: =MONTH(F86) -> 4 | H86: 上海转运中心员工王自文在4月1日早上进港30号卸货码头卸贷，在卸货中右手掌被快件砸中，当时感觉无大碍，下班后去医院检查 | I86: 第2掌骨近段骨折 | J86: 砸伤类 | L86: 责任 | M86: 个人 | O86: 否 | P86: 是
A87: 86 | B87: 管绘云 | C87: 安徽合肥转运中心 | D87: 安徽 | E87: =VLOOKUP(C87,#REF!,3,0) -> #REF! | F87: 45750 | G87: =MONTH(F87) -> 4 | H87: 员工管绘云工号1306965拦截破损时，不小心踩空 | I87: 大腿根部受伤 | J87: 摔伤类 | L87: 无责 | M87: - | O87: 是 | P87: 是
A88: 87 | B88: 李成洋 | C88: 浙江金华义乌转运中心 | D88: 浙江 | E88: =VLOOKUP(C88,#REF!,3,0) -> #REF! | F88: 45751 | G88: =MONTH(F88) -> 4 | H88: 2025年4月4日 20：58分航空部员工李成洋，在拉货的时候滑了，手上的巴枪把大门牙嗑断一半。 | I88: 大门牙嗑断一半 | J88: 摔伤类 | L88: 无责 | M88: - | O88: 否 | P88: 是
A89: 88 | B89: 刘年才 | C89: 广东深圳转运中心 | D89: 广东 | E89: =VLOOKUP(C89,#REF!,3,0) -> #REF! | F89: 45754 | G89: =MONTH(F89) -> 4 | H89: 2025年4月7日01:23:20深圳出港宝安场地后台装车3区后台装车员刘年才在车厢工作中因不慎踩空从伸缩机上掉落 | I89: 1、腰1-4右侧横突骨折；2腰椎间盘突出症 | J89: 摔伤类 | L89: 责任 | M89: 个人 | O89: 否 | P89: 是
A90: 89 | B90: 占检泉 | C90: 江西上饶转运中心 | D90: 江西 | E90: =VLOOKUP(C90,#REF!,3,0) -> #REF! | F90: 45762 | G90: =MONTH(F90) -> 4 | H90: 占检泉（1323067）4月15日5：46分，该员工坐在铅山网点卡位伸缩机上进行分拣作业，将脚放置在伸缩机检修口处，与此同时，铅山网点装车人员将伸缩机进行回缩，导致员工占检泉（1323067）脚趾被伸缩机检修口处链条卷入，当时立即发现，装车人员停止伸缩机回缩，协助占检泉（1323067）将脚从伸缩机内抽出。当班主管即可进行上报，并将伤员送往医院。 | I90: 骨折 | J90: 机械类 | L90: 责任 | M90: 中心 | O90: 是 | P90: 是
A91: 90 | B91: 汪江 | C91: 浙江金华义乌转运中心 | D91: 浙江 | E91: =VLOOKUP(C91,#REF!,3,0) -> #REF! | F91: 45762 | G91: =MONTH(F91) -> 4 | H91: 2025.4.15日22点40分左右，出港晚班细分拉扫员汪江，临时顶岗装车，车子有斜坡脚踩滑了手被皮带机夹了，导致受伤，第一时间送医院就医检查。 | I91: 手部皮肤受伤、擦伤 | J91: 机械类 | L91: 责任 | M91: 中心 | O91: 是 | P91: 是
A92: 91 | B92: 刘志才 | C92: 江西南昌转运中心 | D92: 江西 | E92: =VLOOKUP(C92,#REF!,3,0) -> #REF! | F92: 45765 | G92: =MONTH(F92) -> 4 | H92: 员工刘志才下楼梯上厕所扭伤脚踝 | I92: 右脚内踝骨折 | J92: 劳动损伤类 | L92: 责任 | M92: 个人 | O92: 否 | P92: 是
A93: 92 | B93: 刘建平 | C93: 江苏江阴转运中心 | D93: 江苏 | E93: =VLOOKUP(C93,#REF!,3,0) -> #REF! | F93: 45766 | G93: =MONTH(F93) -> 4 | H93: 2025年4月20日晚01点时48分左右时，员工刘建平在大货卸车区车厢内抱卸重货时，由于自己抱着货物无法看到脚下情况，失足摔落至地面 | I93: 肋骨6/7/8/9处骨折 | J93: 摔伤类 | L93: 责任 | M93: 中心 | O93: 是 | P93: 是
A94: 93 | B94: 向云杨 | C94: 广东揭阳转运中心 | D94: 广东 | E94: =VLOOKUP(C94,#REF!,3,0) -> #REF! | F94: 45766 | G94: =MONTH(F94) -> 4 | H94: 向云杨，工号：（1319920)2025年4月19日凌晨0:57分，装车员工向云杨装完货后发生摔落平台事故。 | I94: 后腰2椎体压缩性骨折 | J94: 摔伤类 | L94: 责任 | M94: 中心 | O94: 是 | P94: 是
A95: 94 | B95: 巩建平 | C95: 陕西西安转运中心 | D95: 西北 | E95: =VLOOKUP(C95,#REF!,3,0) -> #REF! | F95: 45767 | G95: =MONTH(F95) -> 4 | H95: 出港矩阵员工 ：巩建平 工号:1310882，上厕所回工位下直梯违规背向下直梯脚下打滑摔倒 | I95: 第5、6根肋骨骨折 | J95: 摔伤类 | L95: 责任 | M95: 个人 | O95: 否 | P95: 是
A96: 95 | B96: 吴聪青 | C96: 福建闽南转运中心 | D96: 福建 | E96: =VLOOKUP(C96,#REF!,3,0) -> #REF! | F96: 45768 | G96: =MONTH(F96) -> 4 | H96: 2025年4月21日凌晨3点35分左右，进港夜班人工拆包倒包员：吴聪青（1241622），于进港卸货口1号进行卸货作业。期间，前台卸车员夏松（1314795）因觉得闷热，在未提前通知吴聪青的情况下，私自打开中箱门门栓。此举直接导致吴聪青在后续卸货作业时失去重心，不幸发生跌落事故。 | I96: 脊柱疼痛无法起身，后脑勺疼痛明显 | J96: 坠落类 | L96: 责任 | M96: 中心 | O96: 是 | P96: 是
... A112: 111 | B112: 王国军 | C112: 云南昆明转运中心 | D112: 云南 | E112: =VLOOKUP(C112,#REF!,3,0) -> #REF! | F112: 45791 | G112: =MONTH(F112) -> 5 | H112: 卸车员王国军卸车过程中，货物掉落下来砸到脚。 | I112: 脚趾头骨折 | J112: 砸伤类 | L112: 无责 | M112: - | O112: 否 | P112: 是
A113: 112 | B113: 熊行军 | C113: 贵州贵阳转运中心 | D113: 贵州 | E113: 中 | F113: 45791 | G113: 5 | H113: 2025年 5月14日02 时 36 分员工熊行军进行卸货时，右脚踩在高处货物上，左脚与光滑的车厢地面产生摩擦，冲击力导致扭伤到左脚；经医院检查当事人左脚第五跖骨底部骨折 | I113: 左脚 | J113: 劳动损伤类 | L113: 责任 | M113: 个人 | O113: 否 | P113: 是
A114: 113 | B114: 王祥伟 | C114: 福建泉州转运中心 | D114: 福建 | E114: =VLOOKUP(C114,#REF!,3,0) -> #REF! | F114: 45792 | G114: =MONTH(F114) -> 5 | H114: 出港夜班自动化集包 5 班王祥伟伤（ 工号1337148）在拉包的时候，手被流水线夹伤，后由班长带员工去医院进行检查治疗。 | I114: 无骨折，表皮破皮 | J114: 机械类 | L114: 责任 | M114: 中心 | O114: 是 | P114: 是
A115: 114 | B115: 刘娜娜 | C115: 安徽芜湖转运中心 | D115: 安徽 | E115: =VLOOKUP(C115,#REF!,3,0) -> #REF! | F115: 45792 | G115: =MONTH(F115) -> 5 | H115: 员工自述下楼梯时刚好汗水流到眼睛里了，想擦汗所以动作变形。导致下楼梯打了趔趄。扭伤脚。 | I115: 左脚根骨骨折 | J115: 劳动损伤类 | L115: 无责 | M115: - | O115: 否 | P115: 是
A116: 115 | B116: 刘珈邑 | C116: 山东烟台转运中心 | D116: 山东 | E116: =VLOOKUP(C116,#REF!,3,0) -> #REF! | F116: 45794 | G116: =MONTH(F116) -> 5 | H116: 刘珈邑（工号：1334715），班次为半夜班18：30-24：30；2025年5月17日18：00左右上班途中骑行电动车与大货车相撞 | I116: 肋骨骨折以及半月板受损 | J116: 场外交通类 | L116: 无责 | M116: - | O116: 否 | P116: 是
A117: 116 | B117: 周海鹏 | C117: 广东揭阳转运中心 | D117: 广东 | E117: =VLOOKUP(C117,#REF!,3,0) -> #REF! | F117: 45795 | G117: =MONTH(F117) -> 5 | H117: 周海鹏 （工号：1330383） 凌晨2：01分卸货过程中肩膀扭伤。 | I117: 右侧第一前肋骨骨折 | J117: 劳动损伤类 | L117: 无责 | M117: - | O117: 否 | P117: 是
A118: 117 | B118: 黄佐革 | C118: 上海转运中心 | D118: 上海 | E118: =VLOOKUP(C118,#REF!,3,0) -> #REF! | F118: 45795 | G118: =MONTH(F118) -> 5 | H118: 自动化集包员黄佐革（工号1100372）25.5.18日5：11分在进港二楼交叉机集包区6号线185号格口换包时滑倒，左手撑地手腕受伤。 | I118: 左手桡骨远端骨折 | J118: 摔伤类 | L118: 无责 | M118: - | O118: 否 | P118: 是
A119: 118 | B119: 李星星 | C119: 贵州贵阳转运中心 | D119: 贵州 | E119: =VLOOKUP(C119,#REF!,3,0) -> #REF! | F119: 45797 | G119: =MONTH(F119) -> 5 | H119: 员工李星星在流水线交接处分拣货物，被夹伤（疑似手套被带入皮带前段） | I119: 右手中指指骨骨折并伴有软组织损伤 | J119: 机械类 | L119: 责任 | M119: 中心 | O119: 是 | P119: 是
A120: 119 | B120: 陈金峰 | C120: 安徽阜阳转运中心 | D120: 安徽 | E120: =VLOOKUP(C120,#REF!,3,0) -> #REF! | F120: 45798 | G120: =MONTH(F120) -> 5 | H120: 25.5.21日16：11分粗分驳货员-陈金峰（1141590）下直梯时，站踏板上与人聊天。期间双手脱离扶手、从楼梯滑下磕到设备。 | I120: 左侧第6前肋骨骨折 | J120: 摔伤类 | L120: 责任 | M120: 个人 | O120: 否 | P120: 是
A121: 120 | B121: 卯旺 | C121: 浙江金华义乌转运中心 | D121: 浙江 | E121: =VLOOKUP(C121,#REF!,3,0) -> #REF! | F121: 45801 | G121: =MONTH(F121) -> 5 | H121: 龙海路场地主循环线卡件，卯旺(细分拉扫员 工号 1327813)未关停皮带机疏通快件导致左手指夹伤，现已送往医院进一步检查。 | I121: 左手无名指开放性创口 | J121: 机械类 | L121: 责任 | M121: 中心 | O121: 是 | P121: 是
A122: 121 | B122: 李小平 | C122: 湖南衡阳转运中心 | D122: 湖南 | E122: =VLOOKUP(C122,#REF!,3,0) -> #REF! | F122: 45804 | G122: =MONTH(F122) -> 5 | H122: 夜班李小平在上班时间，卸揭阳平板车时候，重心不稳摔倒。 | I122: 腰压缩性骨折 | J122: 摔伤类 | L122: 责任 | M122: 中心 | O122: 是 | P122: 是
A123: 122 | B123: 李绪中 | C123: 四川成都转运中心 | D123: 川藏 | E123: =VLOOKUP(C123,#REF!,3,0) -> #REF! | F123: 45805 | G123: =MONTH(F123) -> 5 | H123: 2025年5月28日10：15分左右，前台卸车员李绪中（1254586）在卸车作业时，高空掉包砸伤鼻梁 | I123: 鼻梁骨折 | J123: 砸伤类 | L123: 无责 | M123: - | O123: 否 | P123: 是
A124: 123 | B124: 谢余阳 | C124: 四川成都转运中心 | D124: 川藏 | E124: =VLOOKUP(C124,#REF!,3,0) -> #REF! | F124: 45806 | G124: =MONTH(F124) -> 5 | H124: 2025.5.28日谢余阳23：10左右下班后，在公司门口红路灯处吃面，吃完面后骑车回家，5月29日00：05分左右由简阳石桥街道石桥大道方向沿成龙简快速路行往成都方向，行至成龙简快速简阳段（简阳至成都）0km+500m辅道路段：发生交通事故，事故发生后在简阳市人民医院就医，经过医院诊断右侧髋臼骨折；右髋关节后脱位。该起交通事故当事人谢余阳骨折同等责任。 | I124: 右侧髋臼骨折；右髋关节后脱位 | J124: 场外交通类 | L124: 无责 | M124: - | O124: 否 | P124: 否
...

Sheet 24年事故（安全侧）
A1: 序号 | B1: 时间 | C1: 省公司 | D1: 中心名称 | E1: 事故类型 | F1: 事故原因 | G1: 事故当事人 | H1: 事故简述 | I1: 上报人 | J1: 事故责任 | K1: 停工天数 | L1: 事故损失 | M1: 是否纳入安全考核 | N1: 备注
A2: 1 | B2: 45661 | C2: 上海 | D2: 上海转运中心 | E2: 交通事故 | F2: 场外 | H2: 2024年1月4日 18:10许，上海省公司客服管理部员工石莉华下班回家，骑电瓶车行至赵重公路/北青公路（重固加油站）位置，和一电瓶车发生碰撞事故。事故造成石莉华膝盖受伤，目前正在医院检查治疗。据石莉华描述已经报警，事故是对方责任。详细情况待警方证明和医院诊断报告为准。 | I2: 徐小兵 | J2: 意外事故/无责任 | M2: 否
A3: 2 | B3: 45661 | C3: 京津冀 | D3: 天津转运中心 | E3: 交通事故 | F3: 场外 | H3: 夜班员工杨雪梅（佩戴头盔）骑电动车带王晓静下班回家正常骑行时与逆行过来的电动三轮车相撞，据杨雪梅描述相撞前已看到对方车辆试图躲避多次躲避后还是相撞，后报警处理，因对方逆行交警判对方全责，医院出具诊断结果俩人均为肌肉损伤及皮外伤。 | I3: 卜海鹏 | J3: 意外事故/无责任 | M3: 否
A4: 3 | B4: 45666 | C4: 广东 | D4: 中山转运中心 | E4: 治安事件 | F4: / | H4: 下班后，在离转运中心正门约200米处（保安视线范围外），两当事人发生口角，随后李勇文将黄柠华推倒到草地拿起石头砸其头部，整个过程持续近一分钟；7:41分员工路过通知晚班主管王剑康，王剑康马上赶往现场，并要求保安封锁现场拨打120、报警等，随后通知中心经理、人资、安全马上赶往现场，120到现场后确认，黄柠华当场死亡。 | I4: 李振楠 | J4: 意外事故/无责任 | M4: 否 | N4: 刑事案件
A5: 4 | B5: 45671 | C5: 广东 | D5: 广州转运中心 | E5: 人伤事故 | F5: 夹伤 | H5: 2024年1月14日10:35中班前台卸货员唐晓端，工号（1162695）由于一个箱子面单未朝上，在卸货口翻面单时，手随着包裹而动，小拇指不慎卷入伸缩机与皮带交接口，他立即拔出，导致小拇指末端指甲和肉脱离，现场管理第一时间将其送往南方医院治疗并上报经理 | I5: 李振楠 | J5: 个人责任事故 | M5: 是 | N5: 缺少安全警示标识
A6: 5 | B6: 45672 | C6: 江苏 | D6: 江阴转运中心 | E6: 意外事故 | F6: 突发疾病 | H6: 2024年1月15日晚上04:33分，江阴转运中心员工谢良敏，在车间西北角位置（出港装货阜阳线）下扶梯打扫卫生时，突然身体不适（疑似癫痫），头晕开始原地转圈，不慎跌倒。随后滚落月台，导致肩膀骨折。 | I6: 卢桂龙 | J6: 意外事故/无责任 | M6: 否
A7: 6 | B7: 45673 | C7: 川藏 | D7: 成都转运中心 | E7: 意外事故 | F7: 突发疾病 | H7: 2024年1月16日早上员工张龙成在走路下班途中（不明原因）倒在简阳石桥够夫人羊肉汤店附近，路人发现并根据员工工牌拨打我司杨文军班长电话同时拨打120送往简阳中医院，在1月16日上午在简阳市中医院进行手术抢救（脑出血开颅手术）至今人员尚未苏醒。 | I7: 李月阳 | J7: 意外事故/无责任 | M7: 否
A8: 7 | B8: 45673 | C8: 山西 | D8: 太原转运中心 | E8: 人伤事故 | F8: 摔伤 | H8: 该员工于1月15日下午17:41分左右，在申通快递有限公司太原分公司食堂后厨因工作需要去检查工作时，因食堂做饭期间，地面有水较滑而摔倒，导致左脚部大拇指受伤，随后前往太原市第二人员医院，被诊断为左足酶趾末节趾骨骨折。 | I8: 席根慧 | J8: 管理责任事故 | M8: 否 | N8: 场地原因
A9: 8 | B9: 45674 | C9: 广东 | D9: 龙华集散中心 | E9: 人伤事故 | F9: 撞伤 | H9: 事故详细经过：员工在拉包时发现有货物包件重叠，在取上层包件时，用力过猛，右手脱手，致使右手中指撞像上层流水线支撑柱焊接处，造成右手中指手筋划伤。 | I9: 李振楠 | J9: 个人责任事故 | M9: 否
A10: 9 | B10: 45676 | C10: 川藏 | D10: 南充转运中心 | E10: 交通事故 | F10: 场外 | H10: 员工下班后回家，骑电瓶车直走路过路口，因小车倒车，惊吓导致摔倒 | I10: 李月阳 | J10: 意外事故/无责任 | M10: 否
A11: 10 | B11: 45678 | C11: 川藏 | D11: 成都转运中心 | E11: 交通事故 | F11: 场外 | H11: 夜班二楼自动化员工胡明贵、刘素莲在下班途中骑行电动摩托车在简阳市石桥人民法院周边被逆行轿车撞伤，人员受伤第一时间拨打120送往简阳市人民医院 | I11: 李月阳 | J11: 意外事故/无责任 | M11: 否
A12: 11 | B12: 45681 | C12: 东北 | D12: 长春转运中心 | E12: 意外事故 | F12: 突发疾病 | H12: 7. 2024年1月23日休息，2024年1月24日6点半上班，6点40-50在车间女厕所晕倒，早上9点半左右同步至人资，人资建议拍片检查，下午16：:30点同步至安全员处，17:00员工拿着医生诊断到人资，门牙卡掉（一颗缺失一半，另外一个松动，医院拍片诊断，神经受损，牙折，晕倒原因：疲劳过度）厕所没有监控，无现场视频。 | I12: 杨贺 | J12: 意外事故/无责任 | M12: 否
A13: 12 | B13: 45684 | C13: 京津冀 | D13: 石家庄转运中心 | E13: 交通事故 | F13: 场外 | H13: 2024年1月27日00:30下班吃饭时间，装车16班班长杜炳辛驾驶私家车，搭载装车19班员工闫彩茹、装车15班员工闫紫珊三人由南向北行驶至和谐街与南车路交叉口处与由东向西行驶的水泥罐车发生碰撞。 一死二伤。 | I13: 卜海鹏 | J13: 意外事故/无责任 | M13: 否
A14: 13 | B14: 45685 | C14: 贵州 | D14: 贵阳转运中心 | E14: 人伤事故 | F14: 摔伤 | H14: 2024年1月27日晚21时15分，员工杨德虎在出港上班期间，外出抽烟在返岗途中，因场地外在下雨，返岗途中踩到积水不慎摔倒，摔倒后头部撞至楼梯踏步棱角处造成此次事故的发生，事故发生后该员工意识清醒，立即到卫生间查看受伤情况，并立即上报当班主管代宏杰，主管到现场了解情况后立即开车送杨德虎至龙里县人民医院进行检查处理，后医院诊断结果为： 1.额部皮下软组织稍肿胀，颅脑CT平扫未见明显脑挫伤及骨折征象，请结合临床，必要时复查； 2.颈椎退行性变，颈椎CT平扫未见明显骨折征象，请结合临床，必要时复查。 | I14: 黄锦 | J14: 意外事故/无责任 | M14: 否 | N14: 场地原因
A15: 14 | B15: 45686 | C15: 广东 | D15: 揭阳转运中心 | E15: 人伤事故 | F15: 砸伤 | H15: 2024年1月29日早晨7点55分，揭阳进港潮阳线平台底下堵件，员工（吴沛锐）下去帮忙疏通，在疏通过程中未能辨识出上方货物掉落风险，导致上方货物掉下砸到头部，现场管理员杨安乐开车送员工到揭东区妇幼保健院进行检查，检查结果为头皮裂伤，保健院出示的诊疗意见是住院治疗。 | I15: 李振楠 | J15: 意外事故/无责任 | M15: 否
A16: 15 | B16: 45688 | C16: 东北 | D16: 哈尔滨转运中心 | E16: 人伤事故 | F16: 摔伤 | H16: 2024年1月31日，因供包台员工上报供包台出现问题，进港白班交叉带班长张国春， 在进入供包台下跨梯时左侧肋骨杠到栏杆上， 因疼痛，中心第一时间送到平房区二四二医院进行检查，拍片确诊为胸壁搓伤， | I16: 杨贺 | J16: 意外事故/无责任 | M16: 否
A17: 16 | B17: 45690 | C17: 广东 | D17: 广州转运中心 | E17: 交通事故 | F17: 场外 | H17: 2024年2月2日13:30中班自动化供件员康春红（工号：1171392）下故班骑电动车在新耀北路33号撞上路边停放的货车，因为当班班长离职， 概员工并未及时上报，自己报警后到医院就医，诊断结果为唇部、牙齿损 述 伤，交通事故责任认定书已出，员工负主要责任，司机负次要责任 | I17: 李振楠 | J17: 意外事故/无责任 | M17: 否
A18: 17 | B18: 45705 | C18: 浙江 | D18: 台州转运中心 | E18: 人伤事故 | F18: 摔伤 | H18: 2024年2月17日21点43分操作主管毛连炳在人工线进行拉错件时，不慎脚底踩空摔落，我司第一时间将其送往台州市第一人民医院，经医生诊断为左肋骨骨裂，需住院进一步观察。因伤势较轻，预估费用1500，住院产生费用自理。 | I18: 陆梦丽 | J18: 个人责任事故 | M18: 否
A19: 18 | B19: 45707 | C19: 上海 | D19: 浦东转运中心 | E19: 治安事件 | F19: / | H19: 两当事人男女朋友关系，2 月 16 日主管王华明联系过当事人赵扎袜未联系上，17 日主管王华明安排喻莎莎去上海南汇工业园区 浦东新区汇成路859号出租屋找敲门没反应，19 日再次安排喻莎莎去出租屋找发现：两当事人赵扎袜、王燕在出租屋内已经死亡，喻莎莎报警，惠园派出所出警，民警到现场进行刑事侦查，具体死因及时间待警方调查，现场发现人员喻莎莎配合派出所做笔录；后续最新情况会第一时间同步输出。 | I19: 徐小兵 | J19: 意外事故/无责任 | M19: 否 | N19: 刑事案件
A20: 19 | B20: 45708 | C20: 河南 | D20: 郑州转运中心 | E20: 意外事故 | F20: 突发疾病 | H20: 2024年2月20日凌晨1:31时许，众悦人力（合作人力供应商，属临时工）装卸工何忠信，51岁，河南尉氏人（郑州中心附近）在装南宁车时身体突发不适，当场晕倒在车厢内，趴在快件上，无摔倒迹象。转运中心第一时间拨打120急救，医护人员1:50到中心给该工人急救，当时该工人心跳已经停止，随后宣布该工人死亡。家属随即赶到，目前当地派出所和省区人事在协调善后工作。 | I20: 李祥 | J20: 意外事故/无责任 | M20: 否 | N20: 三方劳务
A21: 20 | B21: 45713 | C21: 河南 | D21: 漯河转运中心 | E21: 人伤事故 | F21: 夹伤 | H21: 2024年2月25日10:29:10 漯河转运中心员工马文博，在进港3号库卸车口8号摆臂位置，在设备正常运转且未进行停机操作状态将手伸入检修口位置寻找个人物品，导致设备传动轴夹伤右手食指。 | I21: 李祥 | J21: 个人责任事故 | M21: 是 | N21: 个人违规
A22: 21 | B22: 45716 | C22: 江苏 | D22: 南通转运中心 | E22: 交通事故 | F22: 场外交通 | H22: 2024年2月28日中午12:05分，南通转运中心员工陶文友，在东门位置下班途中，骑电动车直行，货车车头右转时处在视野盲区，未发现该员工导致电瓶车撞倒切员工左腿骨折，该事故交警判为大车司机全责。 | I22: 卢桂龙 | J22: 意外事故/无责任 | M22: 否
A23: 22 | B23: 45722 | C23: 湖北 | D23: 武昌转运中心 | E23: 人伤事故 | F23: 砸伤 | H23: 中心扩建网点，安装隔离网增加格口，隔离网太重员工方进社主动帮忙抬隔离网，因作业空间较小后隔离网重心失衡挤压脚背至左脚骰骨骨裂。 | I23: 严飞 | J23: 意外事故/无责任 | K23: 25天 | L23: 1500 | M23: 否
A24: 23 | B24: 45724 | C24: 湖北 | D24: 武昌转运中心 | E24: 交通事故 | F24: 场内交通 | H24: 某员工在卸货口车辆倒车过程中，强行抢着从车辆与伸缩带之间穿过，结果导致被车辆积压在货厢与伸缩带之间 | I24: 严飞 | J24: 个人责任事故 | K24: 15天 | L24: 省区车队自行处理 | M24: 是 | N24: 车辆在场内夹伤员工
A25: 24 | B25: 45726 | C25: 江西 | D25: 南昌转运中心 | E25: 人伤事故 | F25: 卷伤 | H25: 2024年3月10日晚上19:48分，南昌转运中心员工王武群,在A2库dws扫描， 由于dws后端流水线堵货，员工在关闭流水线后去进行疏通的途中，有一节流水线摆轮设备异常未被关闭，导致员工踩踏上去之后摔倒头发卷入其中。 | I25: 舒自强 | J25: 管理责任事故 | M25: 是 | N25: 设备故障
A26: 25 | B26: 45726 | C26: 东北 | D26: 大连转运中心 | E26: 意外事故 | F26: 突发疾病 | H26: 2024年3月10日21:00大连转运中心管理人员于树军，在发车时间给沈阳车司机（李庆权）打电话发车3-4次电话未接通，长春车司机与沈阳车司机（李庆权）相熟去找沈阳车司机（李庆权），21:22分在沈阳车驾驶室内发现沈阳车司机（李庆权），叫其发车，未叫醒，21:23找到现场管理于树军到现场发现沈阳车司机（李庆权）有问题，叫来车队负责人李奇，确认情况，并拨打120急救中心和110报警，120到达现场确定死亡，目前正在等待医院和警方确定死亡 | I26: 杨贺 | J26: 意外事故/无责任 | M26: 否 | N26: 东北车队驾驶员不纳入考核
A27: 26 | B27: 45725 | C27: 福建 | D27: 闽南转运中心 | E27: 人伤事故 | F27: 摔伤 | H27: 3月9日20点40分左右，中心班长戴锦煌在进港办公室下面钢平台上扫描环保袋，因环保袋湿滑，导致不慎踩滑倒，磕到上二楼楼梯底下，至左颞发生受伤，约3.5cm | I27: 庄俊杰 | J27: 个人责任事故 | K27: 1天 | L27: 461 | M27: 否
A28: 27 | B28: 45727 | C28: 上海 | D28: 浦东转运中心 | E28: 火灾事故 | F28: 责任火灾 | H28: 2024年3月12日 04:40许，上海浦东转运中心2号宿舍楼504房间，发生自燃。详细经过：04:41中心员工李凡蓉发现504房间着火，打电话给中心人员吕立华，吕立华迅速赶到现场，现场浓烟明火已经到了门口窗口，迅速采取紧急措施，协调关闭电源，呼救报警。现场组织救援采取干粉灭火器扑救（使用10个），火势控制后使用消防栓将明火扑灭。随后通知消防救援人员火已经扑灭不要来了现场。消防部门回复救援人员已经到达，消防救援部门到达现场将封锁现场，事故原因待消防救援调查判定。 | I28: 徐小兵 | J28: 个人责任事故 | K28: 0 | M28: 是 | N28: 人员违规使用电器未拔开关
A29: 28 | B29: 45729 | C29: 广东 | D29: 揭阳转运中心 | E29: 人伤事故 | F29: 砸伤 | H29: 2024年3月13号早上八点左右，员工(林越茂)在揭阳转运中心进港卸货口工作时，被包裹砸伤脚趾，原因是包裹内部有铁制件，卸货时包裹掉落砸伤脚趾，现场主管滕国根发现后带受伤员工到揭东区人民医院进行治疗，诊断结果为脚趾骨折，医生在脚趾断裂处植入钢钉进行固定，同时员工需要住院治疗进行观察及恢复，现场主管滕国根垫付医药费3125元。后续调取监控，发现是在车厢内部，监控无法看到详细的画面，故无法提供有效的监控视频，另外，和受伤员工沟通时了解到，员工在卸货时，从上往下拉取包裹，拉取到中间时，员工并不知道包裹内部有铁制件，结果包裹滑落，导致脚趾被砸伤，员工本身并无任何违规行为。 | I29: 李振楠 | J29: 个人责任事故 | M29: 否
A30: 29 | B30: 45730 | C30: 江苏 | D30: 苏州转运中心 | E30: 人伤事故 | F30: 砸伤 | H30: 2024年3月13日早上05:39分，苏州转运中心进港1号线细分回流线员工邵刚兵（男53岁，工龄3年）进行分拣作业，过程中由于当时皮带机上积压货物较多，快件掉落砸至该员工脚面上。3月14日上午前往伊山湖医院治疗，医院诊断脚背骨裂。目前该员工正在前往苏州市吴中区人民医院拍片检查中。 | I30: 卢桂龙 | J30: 个人责任事故 | M30: 否
A31: 30 | B31: 45731 | C31: 广东 | D31: 增城转运中心 | E31: 人伤事故 | F31: 砸伤 | H31: 2024年3月15号早上5点32分左右，增城转运中心倒包平台员工李应军在二层倒包平台操作中，拉包时不慎将旁边重物带到，导致被包件旁边的铁制品重物砸伤脚背，随后班长发现后立即将该员工送到南方医院就诊，对受伤部位进行缝针，现已就诊完，经医生建议已回宿舍休息。 | I31: 李振楠 | J31: 个人责任事故 | K31: 3天 | L31: 1035 | M31: 否
A32: 31 | B32: 45732 | C32: 川藏 | D32: 南充转运中心 | E32: 人伤事故 | F32: 夹伤 | H32: 员工毛海艳，上班期间用手取被卡快件，夹伤左手无名指 | I32: 李月阳 | J32: 个人责任事故 | M32: 是
A33: 32 | B33: 45733 | C33: 广东 | D33: 增城转运中心 | E33: 人伤事故 | F33: 砸伤 | H33: 2024年3月17号晚上22:01分左右在装（增城一合肥一班车，皖AG5073）车的过程中因流水线货物一下子来的快没及时拿下来，整包货砸到小腿上，导致膝盖脱臼，韧带断裂。因是在车厢内部监控无法看到详细画面，故无法提供有效的监控视频。 | I33: 李振楠 | J33: 个人责任事故 | M33: 否
A34: 33 | B34: 45734 | C34: 江苏 | D34: 南通转运中心 | E34: 人伤事故 | F34: 摔伤 | H34: 2024年3月18日晚上20:20分，南通转运中心航空班次安徽中悦企业管理服事务有限公司员工翟节斌（男28岁），在航空出港青岛口位置装车过程中，货故车（山东车队车牌鲁AN1287主驾驶宋磊15141088138副驾台百龙15265253738）移动导致该员工从平台摔落，随后120赶往现场将其接走，经诊断右桡骨远端及尺骨茎突骨折，下尺桡关节间隙增宽需消肿后进行手术，该事故交警目前还在判中。 | I34: 卢桂龙 | J34: 个人责任事故 | M34: 是
A35: 34 | B35: 45735 | C35: 浙江 | D35: 杭州转运中心 | E35: 交通事故 | F35: 场外 | H35: 2024年3月19日00:40分，员工鲁先菊在上班路途中，在靖江场地东大门外（靖江街道青六南路加油站往北约100米丁字路口）被外卖员电瓶车逆行撞倒，后送往杭州市萧山区第二人民医院，诊断结果为颅内脑外出血，顶骨骨折， | I35: 王雪祥 | J35: 意外事故/无责任 | M35: 否
A36: 35 | B36: 45735 | C36: 西北 | D36: 西安转运中心 | E36: 意外事故 | F36: 突发疾病 | H36: 2024.3.19-08：56西安转运中心5号线细分拉件员袁拴牢操作扫描时感到身体不适未上报区域管理，头晕导致不慎将头部撞在临猗格口围栏立柱上，事后员工也未上报班组长只请假说头晕，班组长让回家休息，晚上11点左右员工感觉说话不清楚嘴巴扭曲，随即联系朋友送往咸阳市第一人民医院，经医院检查确诊为脑梗，3月20日中午14：00左右家属联系中心经理告知员工在医院治疗，中心安全约谈当班组长和当班现场员工了解情况并调取监控取证，配合省区人资赶往医院了解员工具体病情 | I36: 赵豪杰 | J36: 意外事故/无责任 | M36: 否
A37: 36 | B37: 45737 | C37: 浙江 | D37: 杭州转运中心-大江东 | E37: 人伤事故 | F37: 砸伤 | H37: 2024年03月21日早上08:58分，杭州转运中心员工（设备维养初级助理）李虎，在杭州转运中心-大江东园区机修仓库门口进行滚筒拆卸作业，与（设备维养初级助理）徐军合力放置已拆卸完滚筒时，徐军未通知李虎直接撒手导致滚筒砸落地面，李虎未反应过来右手被滚筒压在地面上，导致右手无名指骨折。 | I37: 王雪祥 | J37: 个人责任事故 | M37: 是
A38: 37 | B38: 45738 | C38: 川藏 | D38: 成都转运中心 | E38: 人伤事故 | F38: 摔伤 | H38: 车辆抵达卸货口后，员工卸货期间卸环保袋时旁边环保袋被带动导致一起掉落，砸到该人员身上，员工重心不稳跌落摔倒导致左桡骨静裂骨折，医生建议静养即可 | I38: 李月阳 | J38: 个人责任事故 | M38: 否
A39: 38 | B39: 45738 | C39: 福建 | D39: 闽南转运中心 | E39: 交通事故 | F39: 场内交通 | H39: 2024年3月22日02点43分左右，出港员工施小伟下班期间驾驶机动车在出港7-9号线场地外围通道撞向出港员工杨国民；目前受伤者情况：多处骨折；膝盖、腰椎、头部均有受伤。后续待医生3-23号进行CT拍片检查、26磁共振检查。 | I39: 沈鸿伟 | J39: 个人责任事故 | M39: 是
A40: 39 | B40: 45738 | C40: 江苏 | D40: 淮安转运中心 | E40: 人伤事故 | F40: 摔伤 | H40: 航空库细分扫描员：徐红芹，2024年3月22日00:30，在装货区6号圈扫描西安，中途去卫生间不慎从平台楼梯踩空，导致左手手腕受伤，当日立即送医。当天在淮安区山阳街道城东社区卫生服务中心检查诊断结果：左侧桡骨端骨折，实际医生反馈问题不大，建议休养一周，员工反馈并无大碍，并坚持要求上班。 | I40: 吕艾萍 | J40: 个人责任事故 | M40: 否 | N40: 迟报
...

Sheet Sheet11
B2: 上海公司 | D2: 赵扎袜 | E2: 否 | F2: 否 | G2: 5.327292e+17 | H2: 0 | I2: 上海南汇工业园区 浦东新区汇成路859号 | J2: 15925261823 | K2: 去世 | L2: 44629 | M2: 意外事故 | N2: 其他 | O2: 赵扎袜与中心另外一个员工王燕，两当事人男女朋友关系，中心2月8日、2月9日、2月16日联系过当事人赵扎袜没有联系上，17 日主管王华明安排喻莎莎去上海南汇工业园区 浦东新区汇成路859号出租屋找敲门没反应，19 日再次安排喻莎莎去出租屋找发现：两当事人赵扎袜、王燕在出租屋内已经死亡，喻莎莎报警，惠园派出所出警，民警到现场进行刑事侦查，具体死因及时间待警方 | P2: 是
B3: 上海公司 | D3: 王燕 | E3: 否 | F3: 否 | G3: 34042119950310362X | H3: 0 | I3: 上海南汇工业园区浦东新区汇成路859号 | J3: 17721307727 | K3: 去世 | L3: 45217 | M3: 意外事故 | N3: 其他 | O3: 王燕与中心另外一个员工赵扎袜，两当事人男女朋友关系，中心分别在2月8日、2月9日、2月16日联系过当事人赵扎袜没有联系上，17 日主管王华明安排喻莎莎去上海南汇工业园区 浦东新区汇成路859号出租屋找敲门没反应，19 日再次安排喻莎莎去出租屋找发现：两当事人赵扎袜、王燕在出租屋内已经死亡，喻莎莎报警，惠园派出所出警，民警到现场进行刑事侦查，具体死因及时间 | P3: 是
